<?xml version="1.0"?>
<robot xmlns:xacro="http://www.ros.org/wiki/xacro"  name="robot">

    <!-- This is an example of a URDF. -->
    <!-- As we move through the file, new things to note will be pointed out. -->
    <!-- It's not meant an example of GOOD design, but an example of some of the various features of URDF/xacro. -->



    <!-- This will include all the contents of example_include.xacro first. Go check it out! -->
    <xacro:include filename="example_include.xacro" />



    <!-- This first link called "world" is empty -->
    <link name="world"></link>


    <!-- A simple fixed joint from our empty world link, to our base. -->
    <!-- The base origin is offset from the world origin. -->
    <joint name="base_joint" type="fixed">
        <origin xyz="1.5 1.0 0" rpy="0 0 0"/>
        <parent link="world"/>
        <child link="base_link"/>        
    </joint>


    <!-- base, z offset to sit the object on the ground -->
    <link name="base_link">
        <visual>
            <origin xyz="0 0 3.5" rpy="0 0 0"/>
            <geometry>
                <box size="16 29 7" />
            </geometry>
            <material name="green">
                <color rgba="0.2 1 0.2 1"/>
            </material>
        </visual>
        <collision>
            <origin xyz="0 0 3.5" rpy="0 0 0"/>
            <geometry>
                <box size="16 29 7" />
            </geometry>
        </collision>
        <xacro:inertial_box mass="500" x="16" y="29" z="7">
            <origin xyz="0 0 3.5" rpy="0 0 0"/>
        </xacro:inertial_box>
    </link>

    <!-- - articulation one joint -->
    <joint name="shoulder_pan" type="revolute">
        <origin xyz="0 7 7" rpy="0 0 0"/>
        <parent link="base_link"/>
        <child link="shoulder_link"/>
        <axis xyz="0 0 1"/>
        <limit lower="${-pi/2}" upper="${pi/2}" velocity="100" effort="100"/> 
    </joint>

    <!-- small plate for the servo which is art 2 -->
    <link name="shoulder_link">
        <visual>
            <origin xyz="0 0 0" rpy="0 0 0"/>
            <geometry>
                <box size="4.2 4.1 2.2" />
            </geometry>
            <material name="black">
                <color rgba="0 0 0 0.91"/>
            </material>
        </visual>
        <collision>
            <origin xyz="0 0 0" rpy="0 0 0"/>
            <geometry>
                <box size="4.2 4.1 2.2" />
            </geometry>
        </collision>
        <xacro:inertial_box mass="50" x="4.2" y="4.1" z="2.2">
            <origin xyz="0 0 0" rpy="0 0 0"/>
        </xacro:inertial_box>
    </link>

    <!-- articulation two joint -->
    <joint name="shoulder_lift" type="revolute">
        <origin xyz="0 1.05 1.1" rpy="0 0 0"/>
        <parent link="shoulder_link"/>
        <child link="humerus_link"/>
        <axis xyz="1 0 0"/>
        <limit lower="${-pi/2}" upper="${pi/2}" velocity="100" effort="100"/> 
    </joint>


    <!-- slider_link is the box skimming across the top of the base. Its parameters are similar to the base_link, however: -->
    <!-- - Instead of explicitly describing a colour, it uses the named material "blue". It knows about "blue" that material was included in example_include.xacro. -->
    <!-- - Instead of explicitly describing the inertia, we use a macro that was defined in the example_include.xacro -->

    <link name="humerus_link">
        <visual>
            <origin xyz="0 1.5 7" rpy="0 0 0"/>
            <geometry>
                <box size="5.5 3 13" />
            </geometry>
            <material name="blue" />
        </visual>
        <collision>
            <origin xyz="0 1.5 7" rpy="0 0 0"/>
            <geometry>
                <box size="5.5 3 13" />
            </geometry>
        </collision>
        <xacro:inertial_box mass="200" x="5.5" y="3" z="13">
            <origin xyz="0 1.5 7" rpy="0 0 0"/>
        </xacro:inertial_box>
    </link>



    <!-- arm_joint describes the rotation of the arm and is centred around the top corner of the slider box. -->
    <!-- - The axis of rotation is -1 in Y, so that positive is "up" -->
    <!-- - The upper limit uses xacro's mathematical features -->
    <joint name="elbow" type="revolute">
        <origin xyz="0 1.5 13" rpy="0 0 0"/>
        <parent link="humerus_link"/>
        <child link="forearm_link"/>
        <axis xyz="1 0 0"/>
        <limit lower="${-pi/2}" upper="${pi/2}" velocity="100" effort="100"/> 
    </joint>


    <!-- arm_link describes the arm -->
    <!-- - We use the "property" feature to define the arm length and radius and use them multiple times -->
    <!-- - The visual/collision origin is set to halfway along the length (similar to the box), but also with a rotation (again using the mathematical features). -->
    <!--   This is because the cylinder extends along the Z axis by default, but we want it to be along the X axis (when the joint is at 0) -->

    <xacro:property name="arm_length" value="11" />
    <xacro:property name="arm_radius" value="2.75" />

    <link name="forearm_link">
        <visual>
            <origin xyz="0 0 5.5" rpy="0 0 0"/>
            <geometry>
                <box size="5.5 3 11" />
            </geometry>
            <material name="blue" />
        </visual>
        <collision>
            <origin xyz="0 0 5.5" rpy="0 0 0"/>
            <geometry>
                <box size="5.5 3 11" />
            </geometry>
        </collision>
        <xacro:inertial_box mass="200" x="5.5" y="3" z="11">
            <origin xyz="0 0 5.5" rpy="0 0 0"/>
        </xacro:inertial_box>
    </link>

    <joint name="wrist_flex" type="revolute">
        <origin xyz="0 0 11" rpy="0 0 0"/>
        <parent link="forearm_link"/>
        <child link="wrist_link"/>
        <axis xyz="1 0 0"/>
        <limit lower="${-pi/2}" upper="${pi/2}" velocity="100" effort="100"/> 
    </joint>

    <link name="wrist_link">
        <visual>
            <origin xyz="0 1.5 3.25" rpy="0 0 0"/>
            <geometry>
                <box size="5.5 5 7.5" />
            </geometry>
            <material name="blue" />
        </visual>
        <collision>
            <origin xyz="0 1.5 3.25" rpy="0 0 0"/>
            <geometry>
                <box size="5.5 5 7.5" />
            </geometry>
        </collision>
        <xacro:inertial_box mass="200" x="5.5" y="5" z="7.5">
            <origin xyz="0 1.5 3.25" rpy="0 0 0"/>
        </xacro:inertial_box>
    </link>

    <joint name="wrist_roll" type="revolute">
        <origin xyz="0 0 7.5" rpy="0 0 0"/>
        <parent link="wrist_link"/>
        <child link="hand_link"/>
        <axis xyz="0 0 1"/>
        <limit effort="100" lower="${-pi/2}" upper="${-pi/2}" velocity="1.0"/>
    </joint>

    <link name="hand_link">
        <visual>
            <origin xyz="0 -1.5 2" rpy="0 0 0"/>
            <geometry>
                <box size="5.5 5 4" />
            </geometry>
            <material name="blue" />
        </visual>
        <collision>
            <origin xyz="0 -1.5 2" rpy="0 0 0"/>
            <geometry>
                <box size="5.5 5 4" />
            </geometry>
        </collision>
        <xacro:inertial_box mass="200" x="5.5" y="5" z="4">
            <origin xyz="0 -1.5 2" rpy="0 0 0"/>
        </xacro:inertial_box>
    </link>

    <!-- gripper -->
    <joint name="grip_left" type="revolute">
        <parent link="hand_link"/>
        <child link="grip_left_link"/>
        <origin xyz="-1.5 0 3" rpy="0 -1.57 0"/>
        <axis xyz="0 -1 0"/>
        <limit lower="-1.57" upper="0" effort="1000" velocity="0.5"/>
    </joint>

    <joint name="grip_right" type="revolute">
        <parent link="hand_link"/>
        <child link="grip_right_link"/>
        <origin xyz="1.5 0 3" rpy="0 1.57 0"/>
        <axis xyz="0 -1 0"/>
        <limit lower="0" upper="1.57" effort="1000" velocity="0.5"/>
        <mimic joint="grip_left" multiplier="-1"/>
    </joint>

    <link name="grip_left_link">
        <visual>
            <origin xyz="0 0 3" rpy="0 0 0"/>
            <geometry>
                <box size="2.8 0.5 5" />
            </geometry>
            <material name="orange" />
        </visual>
        <collision>
            <origin xyz="0 0 3" rpy="0 0 0"/>
            <geometry>
                <box size="2.8 0.5 5" />
            </geometry>
        </collision>
        <xacro:inertial_box mass="1" x="2.8" y="0.5" z="5">
            <origin xyz="0 0 3" rpy="0 0 0"/>
        </xacro:inertial_box>
    </link>

    <link name="grip_right_link">
        <visual>
            <origin xyz="0 0 3" rpy="0 0 0"/>
            <geometry>
                <box size="-2.8 0.5 5" />
            </geometry>
            <material name="orange" />
        </visual>
        <collision>
            <origin xyz="0 0 3" rpy="0 0 0"/>
            <geometry>
                <box size="-2.8 0.5 5" />
            </geometry>
        </collision>
        <xacro:inertial_box mass="1" x="-2.8" y="0.5" z="5">
            <origin xyz="0 0 3" rpy="0 0 0"/>
        </xacro:inertial_box>
    </link>

    <!-- tendons -->
    <joint name="tendon_left" type="revolute">
        <parent link="hand_link"/>
        <child link="tendon_left_link"/>
        <origin xyz="-0.5 0 5" rpy="0 -1.57 0"/>
        <axis xyz="0 -1 0"/>
        <limit lower="-1.57" upper="0" effort="1000" velocity="0.5"/>
        <mimic joint="grip_left"/>
    </joint>

    <joint name="tendon_right" type="revolute">
        <parent link="hand_link"/>
        <child link="tendon_right_link"/>
        <origin xyz="0.5 0 5" rpy="0 1.57 0"/>
        <axis xyz="0 -1 0"/>
        <limit lower="0" upper="1.57" effort="1000" velocity="0.5"/>
        <mimic joint="grip_left" multiplier="-1"/>
    </joint>

    <link name="tendon_left_link">
        <visual>
            <origin xyz="0 0 5" rpy="0 0 0"/>
            <geometry>
                <cylinder radius="0.25" length="3.8" />
            </geometry>
            <material name="orange" />
        </visual>
        <collision>
            <origin xyz="0 0 5" rpy="0 0 0"/>
            <geometry>
                <cylinder radius="0.25" length="3.8" />
            </geometry>
        </collision>
        <xacro:inertial_cylinder mass="1" length="3.8" radius="0.25">
            <origin xyz="0 0 5" rpy="0 0 0"/>
        </xacro:inertial_cylinder>
    </link>

    <link name="tendon_right_link">
        <visual>
            <origin xyz="0 0 5" rpy="0 0 0"/>
            <geometry>
                <cylinder radius="0.25" length="3.8" />
            </geometry>
            <material name="orange" />
        </visual>
        <collision>
            <origin xyz="0 0 5" rpy="0 0 0"/>
            <geometry>
                <cylinder radius="0.25" length="3.8" />
            </geometry>
        </collision>
        <xacro:inertial_cylinder mass="1" length="3.8" radius="0.25">
            <origin xyz="0 0 5" rpy="0 0 0"/>
        </xacro:inertial_cylinder>
    </link>

    <!--fingers-->
    <joint name="finger_left" type="revolute">
        <parent link="grip_left_link"/>
        <child link="finger_left_link"/>
        <origin xyz="0 0 5.5" rpy="0 1.57 0"/>
        <axis xyz="0 -1 0"/>
        <limit lower="-1.57" upper="0" effort="1000" velocity="0.5"/>
        <mimic joint="grip_left" multiplier="-1"/>
    </joint>
    <joint name="finger_right" type="revolute">
        <parent link="grip_right_link"/>
        <child link="finger_right_link"/>
        <origin xyz="0 0 5.5" rpy="0 -1.57 0"/>
        <axis xyz="0 -1 0"/>
        <limit lower="0" upper="1.57" effort="1000" velocity="0.5"/>
        <mimic joint="grip_left"/>
    </joint>

    <link name="finger_left_link">
        <visual>
            <origin xyz="0.5 0 3" rpy="0 0 0"/>
            <geometry>
                <box size="2 0.5 6.2" />
            </geometry>
            <material name="red" />
        </visual>
        <collision>
            <origin xyz="0.5 0 3" rpy="0 0 0"/>
            <geometry>
                <box size="2 0.5 6.2" />
            </geometry>
        </collision>
        <xacro:inertial_box mass="1" x="2" y="0.5" z="6.2">
            <origin xyz="0.5 0 3" rpy="0 0 0"/>
        </xacro:inertial_box>
    </link>

    <link name="finger_right_link">
        <visual>
            <origin xyz="-0.5 0 3" rpy="0 0 0"/>
            <geometry>
                <box size="-2 0.5 6.2" />
            </geometry>
            <material name="red" />
        </visual>
        <collision>
            <origin xyz="-0.5 0 3" rpy="0 0 0"/>
            <geometry>
                <box size="-2 0.5 6.2" />
            </geometry>
        </collision>
        <xacro:inertial_box mass="1" x="-2" y="0.5" z="6.2">
            <origin xyz="-0.5 0 3" rpy="0 0 0"/>
        </xacro:inertial_box>
    </link>

</robot>
