<?xml version="1.0"?>
<robot xmlns:xacro="http://www.ros.org/wiki/xacro"  name="robot">

    <!-- This is an example of a URDF. -->
    <!-- As we move through the file, new things to note will be pointed out. -->
    <!-- It's not meant an example of GOOD design, but an example of some of the various features of URDF/xacro. -->



    <!-- This will include all the contents of example_include.xacro first. Go check it out! -->
    <xacro:include filename="example_include.xacro" />



    <!-- This first link called "world" is empty -->
    <link name="world"></link>


    <!-- A simple fixed joint from our empty world link, to our base. -->
    <!-- The base origin is offset from the world origin. -->
    <joint name="base_joint" type="fixed">
        <origin xyz="1.5 1.0 0" rpy="0 0 0"/>
        <parent link="world"/>
        <child link="base_link"/>        
    </joint>


    <!-- base, z offset to sit the object on the ground -->
    <link name="base_link">
        <visual>
            <origin xyz="0 0 3.5" rpy="0 0 0"/>
            <geometry>
                <box size="16 29 7" />
            </geometry>
            <material name="green">
                <color rgba="0.2 1 0.2 1"/>
            </material>
        </visual>
        <collision>
            <origin xyz="0 0 3.5" rpy="0 0 0"/>
            <geometry>
                <box size="16 29 7" />
            </geometry>
        </collision>
        <xacro:inertial_box mass="500" x="16" y="29" z="7">
            <origin xyz="0 0 3.5" rpy="0 0 0"/>
        </xacro:inertial_box>
    </link>

    <!-- - articulation one joint -->
    <joint name="art1_joint" type="revolute">
        <origin xyz="0 7 7" rpy="0 0 0"/>
        <parent link="base_link"/>
        <child link="servo_link"/>
        <axis xyz="0 0 1"/>
        <limit effort="100" lower="-3.14159" upper="3.14159" velocity="1.0"/>
        <limit effort="100" lower="-6.28318" upper="6.28318" velocity="1.0"/>
    </joint>

    <!-- small plate for the servo which is art 2 -->
    <link name="servo_link">
        <visual>
            <origin xyz="0 0 1.1" rpy="0 0 0"/>
            <geometry>
                <box size="4.2 4.1 2.2" />
            </geometry>
            <material name="black"/>
        </visual>
        <collision>
            <origin xyz="0 0 1.1" rpy="0 0 0"/>
            <geometry>
                <box size="4.2 4.1 2.2" />
            </geometry>
        </collision>
        <xacro:inertial_box mass="50" x="4.2" y="4.1" z="2.2">
            <origin xyz="0 0 1.1" rpy="0 0 0"/>
        </xacro:inertial_box>
    </link>

    <!-- articulation two joint -->
    <joint name="art2_joint" type="revolute">
        <origin xyz="0 1.05 1.1" rpy="0 0 0"/>
        <parent link="servo_link"/>
        <child link="arm_one"/>
        <axis xyz="1 0 0"/>
        <limit lower="${-pi/2}" upper="${pi/2}" velocity="100" effort="100"/> 
    </joint>


    <!-- slider_link is the box skimming across the top of the base. Its parameters are similar to the base_link, however: -->
    <!-- - Instead of explicitly describing a colour, it uses the named material "blue". It knows about "blue" that material was included in example_include.xacro. -->
    <!-- - Instead of explicitly describing the inertia, we use a macro that was defined in the example_include.xacro -->

    <link name="arm_one">
        <visual>
            <origin xyz="0 0 5.4" rpy="0 0 0"/>
            <geometry>
                <box size="5.5 3 13" />
            </geometry>
            <material name="blue" />
        </visual>
        <collision>
            <origin xyz="0 0 5.4" rpy="0 0 0"/>
            <geometry>
                <box size="5.5 3 13" />
            </geometry>
        </collision>
        <xacro:inertial_box mass="200" x="5.5" y="3" z="13">
            <origin xyz="0 0 5.4" rpy="0 0 0"/>
        </xacro:inertial_box>
    </link>

    <joint name="art3_joint" type="revolute">
        <origin xyz="0 0 10.3" rpy="0 0 0"/>
        <parent link="arm_one"/>
        <child link="arm_two"/>
        <axis xyz="1 0 0"/>
        <limit lower="${-pi/2}" upper="${pi/2}" velocity="100" effort="100"/> 
    </joint>

    <link name="arm_two">
        <visual>
            <origin xyz="0 0 5.5" rpy="0 0 0"/>
            <geometry>
                <box size="5.5 3 11" />
            </geometry>
            <material name="blue" />
        </visual>
        <collision>
            <origin xyz="0 0 5.5" rpy="0 0 0"/>
            <geometry>
                <box size="5.5 3 11" />
            </geometry>
        </collision>
        <xacro:inertial_box mass="200" x="5.5" y="3" z="11">
            <origin xyz="0 0 5.5" rpy="0 0 0"/>
        </xacro:inertial_box>
    </link>

    <joint name="art4_joint" type="revolute">
        <origin xyz="0 0 8.7" rpy="0 0 0"/>
        <parent link="arm_two"/>
        <child link="palm_link"/>
        <axis xyz="-1 0 0"/>
        <limit lower="${-pi/2}" upper="${pi/2}" velocity="100" effort="100"/> 
    </joint>

    <link name="palm_link">
        <visual>
            <origin xyz="0 -1.05 0" rpy="0 0 0"/>
            <geometry>
                <box size="4.1 4.2 2.2" />
            </geometry>
            <material name="black" />
        </visual>
        <visual>
            <origin xyz="0 -1.05 3.25" rpy="0 0 0"/>
            <geometry>
                <box size="2.2 4.1 4.2" />
            </geometry>
            <material name="blue" />
        </visual>
        <collision>
            <origin xyz="0 0 4.45" rpy="0 0 0"/>
            <geometry>
                <box size="5.5 3 11" />
            </geometry>
        </collision>
        <xacro:inertial_box mass="200" x="5.5" y="3" z="11">
            <origin xyz="0 0 4.45" rpy="0 0 0"/>
        </xacro:inertial_box>
    </link>

    <xacro:include filename="example_gazebo.xacro" />


</robot>
